Workbook

Sheet README
A1: APICircle Studio - Web App Manual Test Cases
A2: Platform | B2: web
A3: Document owner | B3: QA Engineering
A4: Build under test | B4: Fill in version before each cycle.
A5: Test environment | B5: OS, browser/Electron version, network, vault state.
A6: Last updated | B6: 2026-05-14
A7: Total test cases | B7: 3348
A9: Scope | B9: Covers the APICircle Studio web build (apps/web). OAuth2 uses popup + BroadcastChannel relay. Mock-server runtime is disabled (definitions remain editable). Data persists in IndexedDB; secrets are encrypted via passphrase-derived AES-GCM with the master JWK stored wrapped in IndexedDB.
A11: Combinatorial coverage included
A12: HTTP Method x Body Type matrix | B12: 7 methods x 9 body types (every cell)
A13: Auth x Method matrix | B13: 17 auth schemes x 4 representative methods
A14: Body content variations | B14: JSON/XML/form-data/binary/urlencoded/GraphQL edge cases
A15: Variable interpolation matrix | B15: 15 surfaces x 7 scopes
A16: Changes-to-Push view | B16: 21 entity buckets x 3 operations (Added/Modified/Removed) plus per-field modifies
A17: Git conflict matrix | B17: 18 buckets x 10 conflict shapes + 3 resolution strategies
A18: Mock response matrix | B18: 15 status codes x 8 content types + matching rules + timing
A19: Headers deep matrix | B19: 17 standard headers + 20 edge cases
A20: JSON Schema references | B20: $ref depth, composition, circular, external, validation
A21: Workspace restore round-trip | B21: 23 data types verified after re-clone
A22: History replay matrix | B22: 19 replay scenarios including auth/var/cookie semantics
A23: HTTP method edge cases | B23: GET-with-body, DELETE-with-body, HEAD-with-body, OPTIONS preflight, custom methods
A25: How to use this workbook
A26: 1. | B26: Open the 'Test Cases' sheet. Filters are enabled on every column.
A27: 2. | B27: Pick a module (column B), Test Type (column D), or priority (column L) to scope your session.
A28: 3. | B28: For each row, follow the steps in 'Test Steps' (column G) using 'Test Data' (column H).
A29: 4. | B29: Compare what you see against 'Expected Result' (column I).
A30: 5. | B30: Record what you saw in 'Actual Result' (column J).
A31: 6. | B31: Set 'Status' (column K) to Pass / Fail / Blocked / Skipped / Not Run.
A32: 7. | B32: Add 'Tester' (column M), 'Test Date' (column N), and a defect link in 'Notes' (column O).
A34: Status values | B34: Pass, Fail, Blocked, Skipped, Not Run
A35: Priority values | B35: High, Medium, Low
A36: Test Type values | B36: Functional, Negative, Edge Case, Security, A11y, Performance, Compatibility, UX/UI, Regression
A38: Summary dashboard | B38: The 'Summary' sheet auto-aggregates counts by module, priority, and test type via formulas. Do not edit manually.
A40: Prioritized smoke pass | B40: Filter Priority='High' for a smoke pass (covers OAuth, push/pull, every body type happy path, auth happy paths, JSON schema basics).
A41: Defect tracking | B41: Use column O to link the issue tracker for failed rows.

Sheet Summary
A1: Test Execution Summary - Web
A3: Module | B3: Total | C3: Not Run | D3: Pass | E3: Fail | F3: Blocked | G3: Skipped | H3: Pass %
A4: Workspace Management | B4: =COUNTIF('Test Cases'!B:B,"Workspace Management") | C4: =COUNTIFS('Test Cases'!B:B,"Workspace Management",'Test Cases'!K:K,"Not Run") | D4: =COUNTIFS('Test Cases'!B:B,"Workspace Management",'Test Cases'!K:K,"Pass") | E4: =COUNTIFS('Test Cases'!B:B,"Workspace Management",'Test Cases'!K:K,"Fail") | F4: =COUNTIFS('Test Cases'!B:B,"Workspace Management",'Test Cases'!K:K,"Blocked") | G4: =COUNTIFS('Test Cases'!B:B,"Workspace Management",'Test Cases'!K:K,"Skipped") | H4: =IFERROR(D4/(D4+E4),"-")
A5: Collections & Requests | B5: =COUNTIF('Test Cases'!B:B,"Collections & Requests") | C5: =COUNTIFS('Test Cases'!B:B,"Collections & Requests",'Test Cases'!K:K,"Not Run") | D5: =COUNTIFS('Test Cases'!B:B,"Collections & Requests",'Test Cases'!K:K,"Pass") | E5: =COUNTIFS('Test Cases'!B:B,"Collections & Requests",'Test Cases'!K:K,"Fail") | F5: =COUNTIFS('Test Cases'!B:B,"Collections & Requests",'Test Cases'!K:K,"Blocked") | G5: =COUNTIFS('Test Cases'!B:B,"Collections & Requests",'Test Cases'!K:K,"Skipped") | H5: =IFERROR(D5/(D5+E5),"-")
A6: Request Editor | B6: =COUNTIF('Test Cases'!B:B,"Request Editor") | C6: =COUNTIFS('Test Cases'!B:B,"Request Editor",'Test Cases'!K:K,"Not Run") | D6: =COUNTIFS('Test Cases'!B:B,"Request Editor",'Test Cases'!K:K,"Pass") | E6: =COUNTIFS('Test Cases'!B:B,"Request Editor",'Test Cases'!K:K,"Fail") | F6: =COUNTIFS('Test Cases'!B:B,"Request Editor",'Test Cases'!K:K,"Blocked") | G6: =COUNTIFS('Test Cases'!B:B,"Request Editor",'Test Cases'!K:K,"Skipped") | H6: =IFERROR(D6/(D6+E6),"-")
A7: Body Editor | B7: =COUNTIF('Test Cases'!B:B,"Body Editor") | C7: =COUNTIFS('Test Cases'!B:B,"Body Editor",'Test Cases'!K:K,"Not Run") | D7: =COUNTIFS('Test Cases'!B:B,"Body Editor",'Test Cases'!K:K,"Pass") | E7: =COUNTIFS('Test Cases'!B:B,"Body Editor",'Test Cases'!K:K,"Fail") | F7: =COUNTIFS('Test Cases'!B:B,"Body Editor",'Test Cases'!K:K,"Blocked") | G7: =COUNTIFS('Test Cases'!B:B,"Body Editor",'Test Cases'!K:K,"Skipped") | H7: =IFERROR(D7/(D7+E7),"-")
A8: Body Content Variations | B8: =COUNTIF('Test Cases'!B:B,"Body Content Variations") | C8: =COUNTIFS('Test Cases'!B:B,"Body Content Variations",'Test Cases'!K:K,"Not Run") | D8: =COUNTIFS('Test Cases'!B:B,"Body Content Variations",'Test Cases'!K:K,"Pass") | E8: =COUNTIFS('Test Cases'!B:B,"Body Content Variations",'Test Cases'!K:K,"Fail") | F8: =COUNTIFS('Test Cases'!B:B,"Body Content Variations",'Test Cases'!K:K,"Blocked") | G8: =COUNTIFS('Test Cases'!B:B,"Body Content Variations",'Test Cases'!K:K,"Skipped") | H8: =IFERROR(D8/(D8+E8),"-")
A9: Method x Body Matrix | B9: =COUNTIF('Test Cases'!B:B,"Method x Body Matrix") | C9: =COUNTIFS('Test Cases'!B:B,"Method x Body Matrix",'Test Cases'!K:K,"Not Run") | D9: =COUNTIFS('Test Cases'!B:B,"Method x Body Matrix",'Test Cases'!K:K,"Pass") | E9: =COUNTIFS('Test Cases'!B:B,"Method x Body Matrix",'Test Cases'!K:K,"Fail") | F9: =COUNTIFS('Test Cases'!B:B,"Method x Body Matrix",'Test Cases'!K:K,"Blocked") | G9: =COUNTIFS('Test Cases'!B:B,"Method x Body Matrix",'Test Cases'!K:K,"Skipped") | H9: =IFERROR(D9/(D9+E9),"-")
A10: HTTP Method Edge Cases | B10: =COUNTIF('Test Cases'!B:B,"HTTP Method Edge Cases") | C10: =COUNTIFS('Test Cases'!B:B,"HTTP Method Edge Cases",'Test Cases'!K:K,"Not Run") | D10: =COUNTIFS('Test Cases'!B:B,"HTTP Method Edge Cases",'Test Cases'!K:K,"Pass") | E10: =COUNTIFS('Test Cases'!B:B,"HTTP Method Edge Cases",'Test Cases'!K:K,"Fail") | F10: =COUNTIFS('Test Cases'!B:B,"HTTP Method Edge Cases",'Test Cases'!K:K,"Blocked") | G10: =COUNTIFS('Test Cases'!B:B,"HTTP Method Edge Cases",'Test Cases'!K:K,"Skipped") | H10: =IFERROR(D10/(D10+E10),"-")
A11: Authentication | B11: =COUNTIF('Test Cases'!B:B,"Authentication") | C11: =COUNTIFS('Test Cases'!B:B,"Authentication",'Test Cases'!K:K,"Not Run") | D11: =COUNTIFS('Test Cases'!B:B,"Authentication",'Test Cases'!K:K,"Pass") | E11: =COUNTIFS('Test Cases'!B:B,"Authentication",'Test Cases'!K:K,"Fail") | F11: =COUNTIFS('Test Cases'!B:B,"Authentication",'Test Cases'!K:K,"Blocked") | G11: =COUNTIFS('Test Cases'!B:B,"Authentication",'Test Cases'!K:K,"Skipped") | H11: =IFERROR(D11/(D11+E11),"-")
A12: Auth x Method Matrix | B12: =COUNTIF('Test Cases'!B:B,"Auth x Method Matrix") | C12: =COUNTIFS('Test Cases'!B:B,"Auth x Method Matrix",'Test Cases'!K:K,"Not Run") | D12: =COUNTIFS('Test Cases'!B:B,"Auth x Method Matrix",'Test Cases'!K:K,"Pass") | E12: =COUNTIFS('Test Cases'!B:B,"Auth x Method Matrix",'Test Cases'!K:K,"Fail") | F12: =COUNTIFS('Test Cases'!B:B,"Auth x Method Matrix",'Test Cases'!K:K,"Blocked") | G12: =COUNTIFS('Test Cases'!B:B,"Auth x Method Matrix",'Test Cases'!K:K,"Skipped") | H12: =IFERROR(D12/(D12+E12),"-")
A13: OAuth2 Flows | B13: =COUNTIF('Test Cases'!B:B,"OAuth2 Flows") | C13: =COUNTIFS('Test Cases'!B:B,"OAuth2 Flows",'Test Cases'!K:K,"Not Run") | D13: =COUNTIFS('Test Cases'!B:B,"OAuth2 Flows",'Test Cases'!K:K,"Pass") | E13: =COUNTIFS('Test Cases'!B:B,"OAuth2 Flows",'Test Cases'!K:K,"Fail") | F13: =COUNTIFS('Test Cases'!B:B,"OAuth2 Flows",'Test Cases'!K:K,"Blocked") | G13: =COUNTIFS('Test Cases'!B:B,"OAuth2 Flows",'Test Cases'!K:K,"Skipped") | H13: =IFERROR(D13/(D13+E13),"-")
A14: Variables & Environments | B14: =COUNTIF('Test Cases'!B:B,"Variables & Environments") | C14: =COUNTIFS('Test Cases'!B:B,"Variables & Environments",'Test Cases'!K:K,"Not Run") | D14: =COUNTIFS('Test Cases'!B:B,"Variables & Environments",'Test Cases'!K:K,"Pass") | E14: =COUNTIFS('Test Cases'!B:B,"Variables & Environments",'Test Cases'!K:K,"Fail") | F14: =COUNTIFS('Test Cases'!B:B,"Variables & Environments",'Test Cases'!K:K,"Blocked") | G14: =COUNTIFS('Test Cases'!B:B,"Variables & Environments",'Test Cases'!K:K,"Skipped") | H14: =IFERROR(D14/(D14+E14),"-")
A15: Variable Interpolation Matrix | B15: =COUNTIF('Test Cases'!B:B,"Variable Interpolation Matrix") | C15: =COUNTIFS('Test Cases'!B:B,"Variable Interpolation Matrix",'Test Cases'!K:K,"Not Run") | D15: =COUNTIFS('Test Cases'!B:B,"Variable Interpolation Matrix",'Test Cases'!K:K,"Pass") | E15: =COUNTIFS('Test Cases'!B:B,"Variable Interpolation Matrix",'Test Cases'!K:K,"Fail") | F15: =COUNTIFS('Test Cases'!B:B,"Variable Interpolation Matrix",'Test Cases'!K:K,"Blocked") | G15: =COUNTIFS('Test Cases'!B:B,"Variable Interpolation Matrix",'Test Cases'!K:K,"Skipped") | H15: =IFERROR(D15/(D15+E15),"-")
A16: Headers Deep Matrix | B16: =COUNTIF('Test Cases'!B:B,"Headers Deep Matrix") | C16: =COUNTIFS('Test Cases'!B:B,"Headers Deep Matrix",'Test Cases'!K:K,"Not Run") | D16: =COUNTIFS('Test Cases'!B:B,"Headers Deep Matrix",'Test Cases'!K:K,"Pass") | E16: =COUNTIFS('Test Cases'!B:B,"Headers Deep Matrix",'Test Cases'!K:K,"Fail") | F16: =COUNTIFS('Test Cases'!B:B,"Headers Deep Matrix",'Test Cases'!K:K,"Blocked") | G16: =COUNTIFS('Test Cases'!B:B,"Headers Deep Matrix",'Test Cases'!K:K,"Skipped") | H16: =IFERROR(D16/(D16+E16),"-")
A17: Response Panel | B17: =COUNTIF('Test Cases'!B:B,"Response Panel") | C17: =COUNTIFS('Test Cases'!B:B,"Response Panel",'Test Cases'!K:K,"Not Run") | D17: =COUNTIFS('Test Cases'!B:B,"Response Panel",'Test Cases'!K:K,"Pass") | E17: =COUNTIFS('Test Cases'!B:B,"Response Panel",'Test Cases'!K:K,"Fail") | F17: =COUNTIFS('Test Cases'!B:B,"Response Panel",'Test Cases'!K:K,"Blocked") | G17: =COUNTIFS('Test Cases'!B:B,"Response Panel",'Test Cases'!K:K,"Skipped") | H17: =IFERROR(D17/(D17+E17),"-")
A18: Pre-request Scripts & Tests | B18: =COUNTIF('Test Cases'!B:B,"Pre-request Scripts & Tests") | C18: =COUNTIFS('Test Cases'!B:B,"Pre-request Scripts & Tests",'Test Cases'!K:K,"Not Run") | D18: =COUNTIFS('Test Cases'!B:B,"Pre-request Scripts & Tests",'Test Cases'!K:K,"Pass") | E18: =COUNTIFS('Test Cases'!B:B,"Pre-request Scripts & Tests",'Test Cases'!K:K,"Fail") | F18: =COUNTIFS('Test Cases'!B:B,"Pre-request Scripts & Tests",'Test Cases'!K:K,"Blocked") | G18: =COUNTIFS('Test Cases'!B:B,"Pre-request Scripts & Tests",'Test Cases'!K:K,"Skipped") | H18: =IFERROR(D18/(D18+E18),"-")
A19: History | B19: =COUNTIF('Test Cases'!B:B,"History") | C19: =COUNTIFS('Test Cases'!B:B,"History",'Test Cases'!K:K,"Not Run") | D19: =COUNTIFS('Test Cases'!B:B,"History",'Test Cases'!K:K,"Pass") | E19: =COUNTIFS('Test Cases'!B:B,"History",'Test Cases'!K:K,"Fail") | F19: =COUNTIFS('Test Cases'!B:B,"History",'Test Cases'!K:K,"Blocked") | G19: =COUNTIFS('Test Cases'!B:B,"History",'Test Cases'!K:K,"Skipped") | H19: =IFERROR(D19/(D19+E19),"-")
A20: History Replay Matrix | B20: =COUNTIF('Test Cases'!B:B,"History Replay Matrix") | C20: =COUNTIFS('Test Cases'!B:B,"History Replay Matrix",'Test Cases'!K:K,"Not Run") | D20: =COUNTIFS('Test Cases'!B:B,"History Replay Matrix",'Test Cases'!K:K,"Pass") | E20: =COUNTIFS('Test Cases'!B:B,"History Replay Matrix",'Test Cases'!K:K,"Fail") | F20: =COUNTIFS('Test Cases'!B:B,"History Replay Matrix",'Test Cases'!K:K,"Blocked") | G20: =COUNTIFS('Test Cases'!B:B,"History Replay Matrix",'Test Cases'!K:K,"Skipped") | H20: =IFERROR(D20/(D20+E20),"-")
A21: Cookies | B21: =COUNTIF('Test Cases'!B:B,"Cookies") | C21: =COUNTIFS('Test Cases'!B:B,"Cookies",'Test Cases'!K:K,"Not Run") | D21: =COUNTIFS('Test Cases'!B:B,"Cookies",'Test Cases'!K:K,"Pass") | E21: =COUNTIFS('Test Cases'!B:B,"Cookies",'Test Cases'!K:K,"Fail") | F21: =COUNTIFS('Test Cases'!B:B,"Cookies",'Test Cases'!K:K,"Blocked") | G21: =COUNTIFS('Test Cases'!B:B,"Cookies",'Test Cases'!K:K,"Skipped") | H21: =IFERROR(D21/(D21+E21),"-")
A22: Mock Servers | B22: =COUNTIF('Test Cases'!B:B,"Mock Servers") | C22: =COUNTIFS('Test Cases'!B:B,"Mock Servers",'Test Cases'!K:K,"Not Run") | D22: =COUNTIFS('Test Cases'!B:B,"Mock Servers",'Test Cases'!K:K,"Pass") | E22: =COUNTIFS('Test Cases'!B:B,"Mock Servers",'Test Cases'!K:K,"Fail") | F22: =COUNTIFS('Test Cases'!B:B,"Mock Servers",'Test Cases'!K:K,"Blocked") | G22: =COUNTIFS('Test Cases'!B:B,"Mock Servers",'Test Cases'!K:K,"Skipped") | H22: =IFERROR(D22/(D22+E22),"-")
A23: Mock Response Matrix | B23: =COUNTIF('Test Cases'!B:B,"Mock Response Matrix") | C23: =COUNTIFS('Test Cases'!B:B,"Mock Response Matrix",'Test Cases'!K:K,"Not Run") | D23: =COUNTIFS('Test Cases'!B:B,"Mock Response Matrix",'Test Cases'!K:K,"Pass") | E23: =COUNTIFS('Test Cases'!B:B,"Mock Response Matrix",'Test Cases'!K:K,"Fail") | F23: =COUNTIFS('Test Cases'!B:B,"Mock Response Matrix",'Test Cases'!K:K,"Blocked") | G23: =COUNTIFS('Test Cases'!B:B,"Mock Response Matrix",'Test Cases'!K:K,"Skipped") | H23: =IFERROR(D23/(D23+E23),"-")
A24: Settings & Theming | B24: =COUNTIF('Test Cases'!B:B,"Settings & Theming") | C24: =COUNTIFS('Test Cases'!B:B,"Settings & Theming",'Test Cases'!K:K,"Not Run") | D24: =COUNTIFS('Test Cases'!B:B,"Settings & Theming",'Test Cases'!K:K,"Pass") | E24: =COUNTIFS('Test Cases'!B:B,"Settings & Theming",'Test Cases'!K:K,"Fail") | F24: =COUNTIFS('Test Cases'!B:B,"Settings & Theming",'Test Cases'!K:K,"Blocked") | G24: =COUNTIFS('Test Cases'!B:B,"Settings & Theming",'Test Cases'!K:K,"Skipped") | H24: =IFERROR(D24/(D24+E24),"-")
A25: Import / Export | B25: =COUNTIF('Test Cases'!B:B,"Import / Export") | C25: =COUNTIFS('Test Cases'!B:B,"Import / Export",'Test Cases'!K:K,"Not Run") | D25: =COUNTIFS('Test Cases'!B:B,"Import / Export",'Test Cases'!K:K,"Pass") | E25: =COUNTIFS('Test Cases'!B:B,"Import / Export",'Test Cases'!K:K,"Fail") | F25: =COUNTIFS('Test Cases'!B:B,"Import / Export",'Test Cases'!K:K,"Blocked") | G25: =COUNTIFS('Test Cases'!B:B,"Import / Export",'Test Cases'!K:K,"Skipped") | H25: =IFERROR(D25/(D25+E25),"-")
A26: Git Integration | B26: =COUNTIF('Test Cases'!B:B,"Git Integration") | C26: =COUNTIFS('Test Cases'!B:B,"Git Integration",'Test Cases'!K:K,"Not Run") | D26: =COUNTIFS('Test Cases'!B:B,"Git Integration",'Test Cases'!K:K,"Pass") | E26: =COUNTIFS('Test Cases'!B:B,"Git Integration",'Test Cases'!K:K,"Fail") | F26: =COUNTIFS('Test Cases'!B:B,"Git Integration",'Test Cases'!K:K,"Blocked") | G26: =COUNTIFS('Test Cases'!B:B,"Git Integration",'Test Cases'!K:K,"Skipped") | H26: =IFERROR(D26/(D26+E26),"-")
A27: Changes-to-Push View | B27: =COUNTIF('Test Cases'!B:B,"Changes-to-Push View") | C27: =COUNTIFS('Test Cases'!B:B,"Changes-to-Push View",'Test Cases'!K:K,"Not Run") | D27: =COUNTIFS('Test Cases'!B:B,"Changes-to-Push View",'Test Cases'!K:K,"Pass") | E27: =COUNTIFS('Test Cases'!B:B,"Changes-to-Push View",'Test Cases'!K:K,"Fail") | F27: =COUNTIFS('Test Cases'!B:B,"Changes-to-Push View",'Test Cases'!K:K,"Blocked") | G27: =COUNTIFS('Test Cases'!B:B,"Changes-to-Push View",'Test Cases'!K:K,"Skipped") | H27: =IFERROR(D27/(D27+E27),"-")
A28: Git Conflict Matrix | B28: =COUNTIF('Test Cases'!B:B,"Git Conflict Matrix") | C28: =COUNTIFS('Test Cases'!B:B,"Git Conflict Matrix",'Test Cases'!K:K,"Not Run") | D28: =COUNTIFS('Test Cases'!B:B,"Git Conflict Matrix",'Test Cases'!K:K,"Pass") | E28: =COUNTIFS('Test Cases'!B:B,"Git Conflict Matrix",'Test Cases'!K:K,"Fail") | F28: =COUNTIFS('Test Cases'!B:B,"Git Conflict Matrix",'Test Cases'!K:K,"Blocked") | G28: =COUNTIFS('Test Cases'!B:B,"Git Conflict Matrix",'Test Cases'!K:K,"Skipped") | H28: =IFERROR(D28/(D28+E28),"-")
A29: Workspace Restore from Git | B29: =COUNTIF('Test Cases'!B:B,"Workspace Restore from Git") | C29: =COUNTIFS('Test Cases'!B:B,"Workspace Restore from Git",'Test Cases'!K:K,"Not Run") | D29: =COUNTIFS('Test Cases'!B:B,"Workspace Restore from Git",'Test Cases'!K:K,"Pass") | E29: =COUNTIFS('Test Cases'!B:B,"Workspace Restore from Git",'Test Cases'!K:K,"Fail") | F29: =COUNTIFS('Test Cases'!B:B,"Workspace Restore from Git",'Test Cases'!K:K,"Blocked") | G29: =COUNTIFS('Test Cases'!B:B,"Workspace Restore from Git",'Test Cases'!K:K,"Skipped") | H29: =IFERROR(D29/(D29+E29),"-")
A30: GraphQL | B30: =COUNTIF('Test Cases'!B:B,"GraphQL") | C30: =COUNTIFS('Test Cases'!B:B,"GraphQL",'Test Cases'!K:K,"Not Run") | D30: =COUNTIFS('Test Cases'!B:B,"GraphQL",'Test Cases'!K:K,"Pass") | E30: =COUNTIFS('Test Cases'!B:B,"GraphQL",'Test Cases'!K:K,"Fail") | F30: =COUNTIFS('Test Cases'!B:B,"GraphQL",'Test Cases'!K:K,"Blocked") | G30: =COUNTIFS('Test Cases'!B:B,"GraphQL",'Test Cases'!K:K,"Skipped") | H30: =IFERROR(D30/(D30+E30),"-")
A31: JSON Schema References | B31: =COUNTIF('Test Cases'!B:B,"JSON Schema References") | C31: =COUNTIFS('Test Cases'!B:B,"JSON Schema References",'Test Cases'!K:K,"Not Run") | D31: =COUNTIFS('Test Cases'!B:B,"JSON Schema References",'Test Cases'!K:K,"Pass") | E31: =COUNTIFS('Test Cases'!B:B,"JSON Schema References",'Test Cases'!K:K,"Fail") | F31: =COUNTIFS('Test Cases'!B:B,"JSON Schema References",'Test Cases'!K:K,"Blocked") | G31: =COUNTIFS('Test Cases'!B:B,"JSON Schema References",'Test Cases'!K:K,"Skipped") | H31: =IFERROR(D31/(D31+E31),"-")
A32: Assertions & Execution Plans | B32: =COUNTIF('Test Cases'!B:B,"Assertions & Execution Plans") | C32: =COUNTIFS('Test Cases'!B:B,"Assertions & Execution Plans",'Test Cases'!K:K,"Not Run") | D32: =COUNTIFS('Test Cases'!B:B,"Assertions & Execution Plans",'Test Cases'!K:K,"Pass") | E32: =COUNTIFS('Test Cases'!B:B,"Assertions & Execution Plans",'Test Cases'!K:K,"Fail") | F32: =COUNTIFS('Test Cases'!B:B,"Assertions & Execution Plans",'Test Cases'!K:K,"Blocked") | G32: =COUNTIFS('Test Cases'!B:B,"Assertions & Execution Plans",'Test Cases'!K:K,"Skipped") | H32: =IFERROR(D32/(D32+E32),"-")
A33: Documentation Viewer | B33: =COUNTIF('Test Cases'!B:B,"Documentation Viewer") | C33: =COUNTIFS('Test Cases'!B:B,"Documentation Viewer",'Test Cases'!K:K,"Not Run") | D33: =COUNTIFS('Test Cases'!B:B,"Documentation Viewer",'Test Cases'!K:K,"Pass") | E33: =COUNTIFS('Test Cases'!B:B,"Documentation Viewer",'Test Cases'!K:K,"Fail") | F33: =COUNTIFS('Test Cases'!B:B,"Documentation Viewer",'Test Cases'!K:K,"Blocked") | G33: =COUNTIFS('Test Cases'!B:B,"Documentation Viewer",'Test Cases'!K:K,"Skipped") | H33: =IFERROR(D33/(D33+E33),"-")
A34: Search & Marketplace | B34: =COUNTIF('Test Cases'!B:B,"Search & Marketplace") | C34: =COUNTIFS('Test Cases'!B:B,"Search & Marketplace",'Test Cases'!K:K,"Not Run") | D34: =COUNTIFS('Test Cases'!B:B,"Search & Marketplace",'Test Cases'!K:K,"Pass") | E34: =COUNTIFS('Test Cases'!B:B,"Search & Marketplace",'Test Cases'!K:K,"Fail") | F34: =COUNTIFS('Test Cases'!B:B,"Search & Marketplace",'Test Cases'!K:K,"Blocked") | G34: =COUNTIFS('Test Cases'!B:B,"Search & Marketplace",'Test Cases'!K:K,"Skipped") | H34: =IFERROR(D34/(D34+E34),"-")
A35: Keyboard Shortcuts | B35: =COUNTIF('Test Cases'!B:B,"Keyboard Shortcuts") | C35: =COUNTIFS('Test Cases'!B:B,"Keyboard Shortcuts",'Test Cases'!K:K,"Not Run") | D35: =COUNTIFS('Test Cases'!B:B,"Keyboard Shortcuts",'Test Cases'!K:K,"Pass") | E35: =COUNTIFS('Test Cases'!B:B,"Keyboard Shortcuts",'Test Cases'!K:K,"Fail") | F35: =COUNTIFS('Test Cases'!B:B,"Keyboard Shortcuts",'Test Cases'!K:K,"Blocked") | G35: =COUNTIFS('Test Cases'!B:B,"Keyboard Shortcuts",'Test Cases'!K:K,"Skipped") | H35: =IFERROR(D35/(D35+E35),"-")
A36: Accessibility | B36: =COUNTIF('Test Cases'!B:B,"Accessibility") | C36: =COUNTIFS('Test Cases'!B:B,"Accessibility",'Test Cases'!K:K,"Not Run") | D36: =COUNTIFS('Test Cases'!B:B,"Accessibility",'Test Cases'!K:K,"Pass") | E36: =COUNTIFS('Test Cases'!B:B,"Accessibility",'Test Cases'!K:K,"Fail") | F36: =COUNTIFS('Test Cases'!B:B,"Accessibility",'Test Cases'!K:K,"Blocked") | G36: =COUNTIFS('Test Cases'!B:B,"Accessibility",'Test Cases'!K:K,"Skipped") | H36: =IFERROR(D36/(D36+E36),"-")
A37: Network Conditions | B37: =COUNTIF('Test Cases'!B:B,"Network Conditions") | C37: =COUNTIFS('Test Cases'!B:B,"Network Conditions",'Test Cases'!K:K,"Not Run") | D37: =COUNTIFS('Test Cases'!B:B,"Network Conditions",'Test Cases'!K:K,"Pass") | E37: =COUNTIFS('Test Cases'!B:B,"Network Conditions",'Test Cases'!K:K,"Fail") | F37: =COUNTIFS('Test Cases'!B:B,"Network Conditions",'Test Cases'!K:K,"Blocked") | G37: =COUNTIFS('Test Cases'!B:B,"Network Conditions",'Test Cases'!K:K,"Skipped") | H37: =IFERROR(D37/(D37+E37),"-")
A38: Performance | B38: =COUNTIF('Test Cases'!B:B,"Performance") | C38: =COUNTIFS('Test Cases'!B:B,"Performance",'Test Cases'!K:K,"Not Run") | D38: =COUNTIFS('Test Cases'!B:B,"Performance",'Test Cases'!K:K,"Pass") | E38: =COUNTIFS('Test Cases'!B:B,"Performance",'Test Cases'!K:K,"Fail") | F38: =COUNTIFS('Test Cases'!B:B,"Performance",'Test Cases'!K:K,"Blocked") | G38: =COUNTIFS('Test Cases'!B:B,"Performance",'Test Cases'!K:K,"Skipped") | H38: =IFERROR(D38/(D38+E38),"-")
A39: Security | B39: =COUNTIF('Test Cases'!B:B,"Security") | C39: =COUNTIFS('Test Cases'!B:B,"Security",'Test Cases'!K:K,"Not Run") | D39: =COUNTIFS('Test Cases'!B:B,"Security",'Test Cases'!K:K,"Pass") | E39: =COUNTIFS('Test Cases'!B:B,"Security",'Test Cases'!K:K,"Fail") | F39: =COUNTIFS('Test Cases'!B:B,"Security",'Test Cases'!K:K,"Blocked") | G39: =COUNTIFS('Test Cases'!B:B,"Security",'Test Cases'!K:K,"Skipped") | H39: =IFERROR(D39/(D39+E39),"-")
A40: Cross-Cutting UX | B40: =COUNTIF('Test Cases'!B:B,"Cross-Cutting UX") | C40: =COUNTIFS('Test Cases'!B:B,"Cross-Cutting UX",'Test Cases'!K:K,"Not Run") | D40: =COUNTIFS('Test Cases'!B:B,"Cross-Cutting UX",'Test Cases'!K:K,"Pass") | E40: =COUNTIFS('Test Cases'!B:B,"Cross-Cutting UX",'Test Cases'!K:K,"Fail") | F40: =COUNTIFS('Test Cases'!B:B,"Cross-Cutting UX",'Test Cases'!K:K,"Blocked") | G40: =COUNTIFS('Test Cases'!B:B,"Cross-Cutting UX",'Test Cases'!K:K,"Skipped") | H40: =IFERROR(D40/(D40+E40),"-")
A41: Web-Specific (Browser) | B41: =COUNTIF('Test Cases'!B:B,"Web-Specific (Browser)") | C41: =COUNTIFS('Test Cases'!B:B,"Web-Specific (Browser)",'Test Cases'!K:K,"Not Run") | D41: =COUNTIFS('Test Cases'!B:B,"Web-Specific (Browser)",'Test Cases'!K:K,"Pass") | E41: =COUNTIFS('Test Cases'!B:B,"Web-Specific (Browser)",'Test Cases'!K:K,"Fail") | F41: =COUNTIFS('Test Cases'!B:B,"Web-Specific (Browser)",'Test Cases'!K:K,"Blocked") | G41: =COUNTIFS('Test Cases'!B:B,"Web-Specific (Browser)",'Test Cases'!K:K,"Skipped") | H41: =IFERROR(D41/(D41+E41),"-")
...

Sheet Test Cases
A1: TC ID | B1: Module | C1: Sub-Feature | D1: Test Type | E1: Test Case Title | F1: Pre-conditions | G1: Test Steps (How to Execute) | H1: Test Data | I1: Expected Result | J1: Actual Result | K1: Status | L1: Priority | M1: Tester | N1: Test Date | O1: Notes / Defect ID
A2: TC-WS-0001 | B2: Workspace Management | C2: Create | D2: Functional | E2: Create new local workspace | F2: App is launched. | G2: 1. Workspace switcher. 2. Create new. 3. Name 'QA-Smoke'. | H2: Name: QA-Smoke | I2: Workspace created and active; empty explorer; top bar shows name. | J2: Workspace 'QA-Smoke' was created and became active; top bar updated to '/ QA-Smoke'. However the Editor's Requests tree (explorer) was NOT empty — it showed a seeded 'Sample: GET /anything' request, and the welcome tour confirmed this is intentional ('A sample request is loaded in the sidebar — open it and hit Send to see a real response'). 2 of 3 expected claims pass; 'empty explorer' fails. | K2: Fail | L2: High | M2: Claude Cowork | N2: 2026-05-14 | O2: Build: git 6ca7dbf. Evidence (Cowork screenshots): switcher-open=ss_838454pre, modal=ss_66114xabd, name-typed=ss_5793wy1ao, created=ss_8092jbniv, workspace-tab=ss_8496m0ho7, editor-after=ss_5891in6i7. Either the Expected text or the new-workspace seed behavior needs to change. Defect candidate: empty-explorer-violation. Note: also created stray 'QA-Smoke-WS' workspace from an earlier attempt before re-reading Test Data; cleanup expected in TC-WS-0010/0011.
A3: TC-WS-0002 | B3: Workspace Management | C3: Create | D3: Negative | E3: Reject blank name | F3: Create dialog open. | G3: 1. Empty name. 2. Create. | H3: — | I3: Create disabled or validation error; no workspace created. | J3: With the New workspace dialog open and the name field left blank, the '+ Create workspace' button was visibly disabled. Clicking it had no effect — dialog stayed open, no validation toast/inline error appeared, and no new workspace was added to the switcher list (still: QA-Smoke, QA-Smoke-WS, My Workspace). | K3: Pass | L3: Medium | M3: Claude Cowork | N3: 2026-05-14 | O3: Build: git 6ca7dbf. Evidence: dialog-open=ss_3742iawfb, click-disabled=ss_4382nailx, switcher-after-cancel=ss_0532h1us0. Behavior is 'Create disabled' branch of the OR in Expected.
A4: TC-WS-0003 | B4: Workspace Management | C4: Create | D4: Edge Case | E4: Unicode + emoji name | F4: Create dialog open. | G4: 1. Name 'Café 🚀 测试 αβγ'. 2. Create. | H4: — | I4: Created; name renders correctly in switcher, top bar, persisted state. | J4: Workspace 'Café 🚀 测试 αβγ' was accepted and created. Name rendered correctly in: input field as typed, top bar chip ('/ Café 🚀 测试 αβγ ▼'), switcher list (with ACTIVE badge), and the accessibility tree exposed it as 'Switch workspace (current: Café 🚀 测试 αβγ)'. Survived a full F5 reload with name and active state preserved. | K4: Pass | L4: Low | M4: Claude Cowork | N4: 2026-05-14 | O4: Evidence: typed=ss_11796qjg8, created=ss_3495ktfx5, switcher=ss_0199j84h4, after-reload=ss_53234iz0l.
A5: TC-WS-0004 | B5: Workspace Management | C5: Create | D5: Edge Case | E5: 256-char name truncation/rejection | F5: Create dialog open. | G5: 1. Paste 256-char name. 2. Create. | H5: 256 chars | I5: Either truncated to documented limit, or clear validation error; UI does not break. | J5: Pasted a 256-char alphanumeric name. The app accepted it without any documented length limit: no client-side truncation (full 256 chars are stored — accessibility name on the switcher chip exposes the entire string), and no validation error displayed. The top bar applies CSS ellipsis for display only ('ABCDEFGHIJKLMNOPQRSTUVW…'), but that is presentational, not an input limit. UI did not crash or visibly break. Fails 'truncated to documented limit OR clear validation error' clause; passes 'UI does not break'. | K5: Fail | L5: Low | M5: Claude Cowork | N5: 2026-05-14 | O5: Evidence: typed=ss_1504eefwh, created=ss_3814wzvvx. Defect candidate: no input length limit on workspace name. Need product decision on whether to add a documented max length.
A6: TC-WS-0005 | B6: Workspace Management | C6: Create | D6: Edge Case | E6: Whitespace-only name rejected | F6: Create dialog. | G6: 1. Name ' '. | H6: — | I6: Validation error; create blocked. | J6: Typed three spaces into the workspace name input. The '+ Create workspace' button remained disabled (visibly dimmed). Clicking it produced no effect — dialog stayed open, no new workspace appeared in the switcher list, top bar still showed the previous (256-char) active workspace. Treats whitespace-only as empty. | K6: Pass | L6: Low | M6: Claude Cowork | N6: 2026-05-14 | O6: Evidence: whitespace-typed=ss_3058r7m5n, click-on-disabled=ss_43563d149.
A7: TC-WS-0006 | B7: Workspace Management | C7: Create | D7: Negative | E7: Duplicate workspace name allowed (UUID id) | F7: Workspace 'A' exists. | G7: 1. Create another 'A'. | H7: — | I7: Allowed by id, but switcher disambiguates via secondary label or recent timestamp. | J7: Attempted to create a second workspace also named 'A' (workspace 'A' already existed from setup). The dialog showed an inline validation error 'A workspace named "A" already exists' in red beneath the input, and the '+ Create workspace' button was disabled. Duplicate workspace name was NOT allowed. Top bar / switcher still has only one 'A' after the attempt. | K7: Fail | L7: Low | M7: Claude Cowork | N7: 2026-05-14 | O7: Evidence: duplicate-rejected=ss_1993v014t. Expected says duplicates should be allowed (UUID id) with switcher disambiguation; implementation enforces unique names by display label. Defect candidate (or test-plan update): align on whether duplicates are allowed or rejected.
A8: TC-WS-0007 | B8: Workspace Management | C8: Switcher | D8: Functional | E8: Switch between two workspaces | F8: Workspaces A and B exist. | G8: 1. Open switcher. 2. Pick B. | H8: — | I8: Active workspace = B; explorer/envs/history reflect B. | J8: Pre-state: workspace 'A' was active and a second workspace 'QA-Smoke' existed. Opened switcher, clicked 'QA-Smoke'. Top bar updated to '/ QA-Smoke', accessibility name became 'Switch workspace (current: QA-Smoke)'. Editor sidebar (explorer) reloaded; Environments / History / Mocks remained accessible. Active workspace transition observed end-to-end. | K8: Pass | L8: High | M8: Claude Cowork | N8: 2026-05-14 | O8: Evidence: switcher-open-with-A=ss_7793z0oly, after-switch=ss_0045tci7y. Note: each workspace ships a seeded sample request (cf. TC-WS-0001 Fail), so the explorer content of A and QA-Smoke looked similar in trees, but the active-workspace context did switch.
A9: TC-WS-0008 | B9: Workspace Management | C9: Switcher | D9: Functional | E9: Recent workspaces persist across restart | F9: 3 workspaces opened. | G9: 1. Restart app. 2. Open switcher. | H9: — | I9: 3 workspaces listed in last-opened order; last-active restored. | J9: Pre-state: 6 workspaces existed (QA-Smoke active). Triggered F5 reload (web 'restart' equivalent). After reload: top bar still shows '/ QA-Smoke', accessibility name confirms 'current: QA-Smoke'. Opening switcher shows all 6 workspaces persisted (QA-Smoke, A, [256-char one], Café 🚀 测试 αβγ, QA-Smoke-WS, My Workspace), with the last-active (QA-Smoke) listed first. | K9: Pass | L9: High | M9: Claude Cowork | N9: 2026-05-14 | O9: Evidence: after-reload=ss_3101d86ee, switcher-after-reload=ss_09288rgm4. Note: row's Pre says '3 workspaces opened' — the test ran with 6 instead, but the persistence + last-active-restoration behavior is what's being graded and it held. F5 is the web equivalent of 'restart app' since this is a SPA backed by IndexedDB.
A10: TC-WS-0009 | B10: Workspace Management | C10: Switcher | D10: UX/UI | E10: Recent list shows last-active first | F10: — | G10: 1. Use 3 workspaces in order A→B→C. 2. Open switcher. | H10: — | I10: Order: C, B, A. | J10: Used 3 workspaces in sequence A → QA-Smoke-WS → My Workspace. Opening the switcher then showed the top 3 entries in MRU order: My Workspace (active), QA-Smoke-WS, A — matching the Expected 'C, B, A' ordering. Older workspaces (QA-Smoke, the 256-char one, Café 🚀 测试 αβγ) followed below in their prior MRU order. | K10: Pass | L10: Low | M10: Claude Cowork | N10: 2026-05-14 | O10: Evidence: after-sequence=ss_84097t6aw, switcher-mru=ss_88749axld. Behavior: switcher always lists active first, then descending recency.
A11: TC-WS-0010 | B11: Workspace Management | C11: Delete | D11: Functional | E11: Delete requires confirmation | F11: Workspace 'Disposable' active. | G11: 1. Settings → Delete. 2. Cancel. | H11: — | I11: Destructive confirm shown; on cancel, workspace remains. | J11: Active workspace QA-Smoke-WS. The Test Steps say 'Settings → Delete' but no Delete control exists inside the Settings menu (Settings menu is app-level: Appearance/Behavior). Delete UX path is instead via the workspace switcher dropdown: a trash icon next to each workspace row. Clicking 'Delete QA-Smoke-WS' opened a modal titled 'Delete QA-Smoke-WS?' with destructive body text ('Removes the workspace and every request, environment, link, and release inside it from this browser. The workspace's GitHub repo (if connected) is untouched. This cannot be undone.') and two buttons: Cancel + Delete workspace (red). Clicked Cancel — modal closed, workspace QA-Smoke-WS remained in the switcher and stayed active. Behavior matches the OBSERVABLE expectations even though the path to it differs from the steps. | K11: Pass | L11: High | M11: Claude Cowork | N11: 2026-05-14 | O11: Evidence: settings-menu=ss_77815o1d6, settings-content=ss_5509fo447, switcher-with-trash=ss_2669fgu5m, confirm-dialog=ss_3992chltr, after-cancel=ss_8050oymjn. Test Steps minor inaccuracy: should say 'Workspace switcher → trash icon' not 'Settings → Delete'.
A12: TC-WS-0011 | B12: Workspace Management | C12: Delete | D12: Functional | E12: Confirm deletion removes from registry | F12: Disposable active. | G12: 1. Delete → Confirm. | H12: — | I12: Removed; app switches to another workspace or empty state; persists across restart. | J12: Active workspace QA-Smoke-WS. Clicked the trash icon in the switcher → confirm dialog appeared → clicked 'Delete workspace' (destructive red). The workspace was removed; the app auto-switched to 'My Workspace' (accessibility name: 'Switch workspace (current: My Workspace)'). After F5 reload, switcher lists 5 workspaces (My Workspace, A, QA-Smoke, ABCDEFG..., Café 🚀 测试 αβγ); QA-Smoke-WS is no longer present. Deletion is persisted across reload. | K12: Pass | L12: High | M12: Claude Cowork | N12: 2026-05-14 | O12: Evidence: about-to-confirm=ss_9753vgu80, after-delete=ss_7302nbe7m. App's auto-switch target is 'My Workspace' (the next workspace in the list). All 3 Expected clauses observed: removed-from-registry / switch-to-another / persist-across-restart.
... A34: TC-WS-0033 | B34: Workspace Management | C34: Cross-Tab Sync | D34: Edge Case | E34: Tab B refresh picks up Tab A's push | F34: Tab A pushed. | G34: 1. Tab B → Refresh button. | H34: — | I34: Tab B fetches latest; UI reflects. | J34: Push works in single-tab; cross-tab refresh-after-push is functionally testable now. Re-attempting: would push in Tab A then click Refresh in Tab B, expecting Tab B to fetch and reflect. Not run in this batch — pushing further would risk leaving the test branch in an unpredictable state for the next session. | K34: Blocked | L34: Medium | M34: Claude Cowork | N34: 2026-05-14 | O34: Blocker (soft): runnable now in principle; deferring to a future Cowork session to keep the working branch deterministic for resume.
A35: TC-CR-0001 | B35: Collections & Requests | C35: Collection | D35: Functional | E35: Create collection at root | F35: Workspace open. | G35: 1. + Add → Collection. 2. Name 'Smoke Suite'. | H35: — | I35: Added at root, selected, empty; rename input focused. | K35: Not Run | L35: High
A36: TC-CR-0002 | B36: Collections & Requests | C36: Collection | D36: Functional | E36: Rename collection inline | F36: Collection 'Old' exists. | G36: 1. Double-click → 'New'. 2. Enter. | H36: — | I36: Name updates in tree and breadcrumbs of open tabs. | K36: Not Run | L36: Medium
A37: TC-CR-0003 | B37: Collections & Requests | C37: Collection | D37: Edge Case | E37: Duplicate name at same level | F37: Collection 'Users' exists. | G37: 1. Create another 'Users' at root. | H37: — | I37: Either auto-suffix or warning; both exist with unique ids. | K37: Not Run | L37: Low
A38: TC-CR-0004 | B38: Collections & Requests | C38: Collection | D38: Functional | E38: Delete empty collection | F38: Empty 'Trash' exists. | G38: 1. Delete → Confirm. | H38: — | I38: Removed from tree. | K38: Not Run | L38: Medium
A39: TC-CR-0005 | B39: Collections & Requests | C39: Collection | D39: Functional | E39: Delete collection cascades to children | F39: Collection with 2 folders + 5 requests. | G39: 1. Delete → Confirm. | H39: — | I39: Warning mentions child counts; all descendants removed. | K39: Not Run | L39: High
A40: TC-CR-0006 | B40: Collections & Requests | C40: Collection | D40: Functional | E40: Duplicate collection deep-copies tree | F40: Collection with 3 nested folders + 4 requests. | G40: 1. Right-click → Duplicate. | H40: — | I40: New collection has identical tree; ids new; original unmodified. | K40: Not Run | L40: Medium
A41: TC-CR-0007 | B41: Collections & Requests | C41: Folder | D41: Functional | E41: Create folder under collection | F41: Collection 'API v1' exists. | G41: 1. Add folder 'Users'. | H41: — | I41: Added; expand/collapse works. | K41: Not Run | L41: High
A42: TC-CR-0008 | B42: Collections & Requests | C42: Folder | D42: Edge Case | E42: 5-level nesting | F42: — | G42: 1. Create A→B→C→D→E. | H42: — | I42: All levels render with distinct indents. | K42: Not Run | L42: Low
A43: TC-CR-0009 | B43: Collections & Requests | C43: Folder | D43: Functional | E43: Folder auth inherited by requests | F43: Folder with Bearer auth. | G43: 1. Create child request set auth=Inherit. 2. Send. | H43: — | I43: Child uses folder's Bearer. | K43: Not Run | L43: High
A44: TC-CR-0010 | B44: Collections & Requests | C44: Request | D44: Functional | E44: Create via Ctrl+N | F44: Editor focused; collection selected. | G44: 1. Ctrl/Cmd+N. | H44: — | I44: GET 'Untitled Request' created under selection; URL focused. | K44: Not Run | L44: High
A45: TC-CR-0011 | B45: Collections & Requests | C45: Request | D45: Functional | E45: Duplicate clones all fields | F45: Request fully configured. | G45: 1. Duplicate. | H45: — | I45: '(copy)' with cloned URL/method/headers/body/auth/scripts/tests. | K45: Not Run | L45: Medium
A46: TC-CR-0012 | B46: Collections & Requests | C46: Request | D46: Functional | E46: Delete keeps history readable | F46: Request with prior runs. | G46: 1. Delete → Confirm. | H46: — | I46: Tree removes it; History panel still shows old runs by URL/method. | K46: Not Run | L46: Medium
... A377: TC-WB-0027 | B377: Web-Specific (Browser) | C377: Visibility | D377: Edge Case | E377: Hidden during OAuth callback | F377: - | G377: 1. Hide; approve. | H377: - | I377: BroadcastChannel delivers regardless. | K377: Not Run | L377: Medium
A378: TC-MM-0001 | B378: Method x Body Matrix | C378: GET x none | D378: Functional | E378: GET with body type 'none' | F378: Editor open. | G378: 1. New request; method GET. 2. Body type none; provide minimal valid content. 3. Send to https://httpbin.org/anything (or equivalent echo). | H378: method=GET; body=none | I378: Request sent with no body; Content-Type not set; server returns expected status. | J378: Set method=GET, URL=https://httpbin.org/anything, body type=none. Clicked Send. Response: HTTP 200, 1463 ms, 1.15 KB body, 987 B on wire. The request reached httpbin (status indicates round-trip) and no errors were thrown. Content-Type header not sent (verified by 'No entries yet' in Headers tab plus body=none in the editor). Server returned expected 200 for a body-less GET. | K378: Pass | L378: High | M378: Claude Cowork | N378: 2026-05-14 | O378: Evidence: response-panel=ss_1411vqq57. Mechanical send/receive verified; the response Body editor takes ~1-2 s to populate beyond the headline but the headline metrics are the operative observable.
A379: TC-MM-0002 | B379: Method x Body Matrix | C379: GET x form-data | D379: Edge Case | E379: GET with body type 'form-data' | F379: Editor open. | G379: 1. New request; method GET. 2. Body type form-data; provide minimal valid content. 3. Send to https://httpbin.org/anything (or equivalent echo). | H379: method=GET; body=form-data | I379: Client allows configuring a form-data body for GET; on send, RFC-discouraged combination is transmitted as-is. Verify httpbin/echo endpoint receives the body OR app warns about violation but still sends. | K379: Not Run | L379: Medium
A380: TC-MM-0003 | B380: Method x Body Matrix | C380: GET x x-www-form-urlencoded | D380: Edge Case | E380: GET with body type 'x-www-form-urlencoded' | F380: Editor open. | G380: 1. New request; method GET. 2. Body type x-www-form-urlencoded; provide minimal valid content. 3. Send to https://httpbin.org/anything (or equivalent echo). | H380: method=GET; body=x-www-form-urlencoded | I380: Client allows configuring a x-www-form-urlencoded body for GET; on send, RFC-discouraged combination is transmitted as-is. Verify httpbin/echo endpoint receives the body OR app warns about violation but still sends. | K380: Not Run | L380: Medium
A381: TC-MM-0004 | B381: Method x Body Matrix | C381: GET x raw-json | D381: Edge Case | E381: GET with body type 'raw-json' | F381: Editor open. | G381: 1. New request; method GET. 2. Body type raw-json; provide minimal valid content. 3. Send to https://httpbin.org/anything (or equivalent echo). | H381: method=GET; body=raw-json | I381: Client allows configuring a raw-json body for GET; on send, RFC-discouraged combination is transmitted as-is. Verify httpbin/echo endpoint receives the body OR app warns about violation but still sends. | K381: Not Run | L381: Medium
A382: TC-MM-0005 | B382: Method x Body Matrix | C382: GET x raw-xml | D382: Edge Case | E382: GET with body type 'raw-xml' | F382: Editor open. | G382: 1. New request; method GET. 2. Body type raw-xml; provide minimal valid content. 3. Send to https://httpbin.org/anything (or equivalent echo). | H382: method=GET; body=raw-xml | I382: Client allows configuring a raw-xml body for GET; on send, RFC-discouraged combination is transmitted as-is. Verify httpbin/echo endpoint receives the body OR app warns about violation but still sends. | K382: Not Run | L382: Medium
A383: TC-MM-0006 | B383: Method x Body Matrix | C383: GET x raw-html | D383: Edge Case | E383: GET with body type 'raw-html' | F383: Editor open. | G383: 1. New request; method GET. 2. Body type raw-html; provide minimal valid content. 3. Send to https://httpbin.org/anything (or equivalent echo). | H383: method=GET; body=raw-html | I383: Client allows configuring a raw-html body for GET; on send, RFC-discouraged combination is transmitted as-is. Verify httpbin/echo endpoint receives the body OR app warns about violation but still sends. | K383: Not Run | L383: Medium
A384: TC-MM-0007 | B384: Method x Body Matrix | C384: GET x raw-text | D384: Edge Case | E384: GET with body type 'raw-text' | F384: Editor open. | G384: 1. New request; method GET. 2. Body type raw-text; provide minimal valid content. 3. Send to https://httpbin.org/anything (or equivalent echo). | H384: method=GET; body=raw-text | I384: Client allows configuring a raw-text body for GET; on send, RFC-discouraged combination is transmitted as-is. Verify httpbin/echo endpoint receives the body OR app warns about violation but still sends. | K384: Not Run | L384: Medium
A385: TC-MM-0008 | B385: Method x Body Matrix | C385: GET x binary | D385: Edge Case | E385: GET with body type 'binary' | F385: Editor open. | G385: 1. New request; method GET. 2. Body type binary; provide minimal valid content. 3. Send to https://httpbin.org/anything (or equivalent echo). | H385: method=GET; body=binary | I385: Client allows configuring a binary body for GET; on send, RFC-discouraged combination is transmitted as-is. Verify httpbin/echo endpoint receives the body OR app warns about violation but still sends. | K385: Not Run | L385: Medium
A386: TC-MM-0009 | B386: Method x Body Matrix | C386: GET x graphql | D386: Edge Case | E386: GET with body type 'graphql' | F386: Editor open. | G386: 1. New request; method GET. 2. Body type graphql; provide minimal valid content. 3. Send to https://httpbin.org/anything (or equivalent echo). | H386: method=GET; body=graphql | I386: Client allows configuring a graphql body for GET; on send, RFC-discouraged combination is transmitted as-is. Verify httpbin/echo endpoint receives the body OR app warns about violation but still sends. | K386: Not Run | L386: Medium
A387: TC-MM-0010 | B387: Method x Body Matrix | C387: POST x none | D387: Functional | E387: POST with body type 'none' | F387: Editor open. | G387: 1. New request; method POST. 2. Body type none; provide minimal valid content. 3. Send to https://httpbin.org/anything (or equivalent echo). | H387: method=POST; body=none | I387: Request sent with no body; Content-Type not set; server may return 411 Length-Required or 200 depending on endpoint. | K387: Not Run | L387: Medium
A388: TC-MM-0011 | B388: Method x Body Matrix | C388: POST x form-data | D388: Functional | E388: POST with body type 'form-data' | F388: Editor open. | G388: 1. New request; method POST. 2. Body type form-data; provide minimal valid content. 3. Send to https://httpbin.org/anything (or equivalent echo). | H388: method=POST; body=form-data | I388: POST sent as multipart/form-data; boundary set; server echo confirms parsed fields/files. | K388: Not Run | L388: High
A389: TC-MM-0012 | B389: Method x Body Matrix | C389: POST x x-www-form-urlencoded | D389: Functional | E389: POST with body type 'x-www-form-urlencoded' | F389: Editor open. | G389: 1. New request; method POST. 2. Body type x-www-form-urlencoded; provide minimal valid content. 3. Send to https://httpbin.org/anything (or equivalent echo). | H389: method=POST; body=x-www-form-urlencoded | I389: POST sent with application/x-www-form-urlencoded body; server parses fields. | K389: Not Run | L389: High
A390: TC-MM-0013 | B390: Method x Body Matrix | C390: POST x raw-json | D390: Functional | E390: POST with body type 'raw-json' | F390: Editor open. | G390: 1. New request; method POST. 2. Body type raw-json; provide minimal valid content. 3. Send to https://httpbin.org/anything (or equivalent echo). | H390: method=POST; body=raw-json | I390: POST sent with application/json body; server parses JSON. | K390: Not Run | L390: High
... A3349: TC-CG-0242 | B3349: Code Generation | C3349: Edge | D3349: Edge Case | E3349: Codegen for AWS SigV4 includes signing helper or note | F3349: AWS request. | G3349: 1. Generate. | H3349: - | I3349: Either uses SDK call or includes inline signing; not just hardcoded signature. | K3349: Not Run | L3349: Medium
